Workbook

Sheet Duke release copy DEV
A1: Key | B1: FIGMA | C1: en-US | D1: en-CA | E1: en-GB | F1: da-DK | G1: de-DE | H1: de-CH | I1: fr-FR | J1: fr-CH | K1: fr-BE | L1: fr-CA | M1: it-IT | N1: it-CH | O1: ja-JP | P1: es-MX | Q1: nl-NL | R1: nb-NO | S1: es-ES | T1: sv-SE | U1: en-AU | V1: en-NZ | W1: en-RW | X1: zh-CN | Y1: cs-CZ | Z1: fi-FI | AA1: pl-PL | AB1: de-LU | AC1: fr-LU | AD1: es-CO
A2: fet-feature-dimensions | B2: Dimensions | C2: Dimensions | D2: Dimensions | E2: Dimensions | F2: Mål | G2: Abmessungen | H2: Abmessungen | I2: Dimensions | J2: Dimensions | K2: Dimensions | L2: Dimensions | M2: Dimensioni | N2: Dimensioni | O2: 寸法 | P2: Dimensiones | Q2: Afmetingen | R2: Mål | S2: Dimensiones | T2: Mått | U2: Dimensions | V2: Dimensions | W2: Dimensions | X2: 尺寸 | Y2: Rozměry | Z2: Mitat | AA2: Wymiary | AB2: Abmessungen | AC2: Dimensions | AD2: Dimensiones
A3: fet-feature-weight | B3: Weight | C3: Weight | D3: Weight | E3: Weight | F3: Vægt | G3: Gewicht | H3: Gewicht | I3: Poids | J3: Poids | K3: Poids | L3: Poids | M3: Peso | N3: Peso | O3: 重量 | P3: Peso | Q3: Gewicht | R3: Vekt | S3: Peso | T3: Vikt | U3: Weight | V3: Weight | W3: Weight | X3: 重量 | Y3: Hmotnost | Z3: Paino | AA3: Waga | AB3: Gewicht | AC3: Poids | AD3: Peso
A4: fet-feature-weight-arc | C4: 13.78 lbs (6.25 kg) | D4: 13.78 lb (6.25 kg) | E4: 13.78 lb (6.25 kg) | F4: 6,25 kg | G4: 6,25 kg | H4: 6,25 kg | I4: 6,25 kg | J4: 6,25 kg | K4: 6,25 kg | L4: 6,25 kg (13,78 lb) | M4: 6,25 kg (13,78 lb) | N4: 6,25 kg (13,78 lb) | O4: 6.25 kg | P4: 6.25 kg (13.78 lb) | Q4: 6,25 kg | R4: 6,25 kg | S4: 6,25 kg (13,78 lb) | T4: 6,25 kg | U4: 6.25 kg | V4: 6.25 kg | W4: 13.78 lb (6.25 kg) | X4: 6.25千克（13.78磅） | Y4: 13,78 libry (6,25 kg) | Z4: 6,25 kg | AA4: 6,25 kg | AB4: 6,25 kg | AC4: 6,25 kg | AD4: 6,25 kg (13,78 lb)
A5: fet-feature-weight-beam | B5: 6.2 lbs (2.8 kg) | C5: 6.2 lbs (2.8 kg) | D5: 6.2 lb (2.8 kg) | E5: 6.2 lb (2.8 kg) | F5: 2,8 kg | G5: 2,8 kg | H5: 2,8 kg | I5: 2,8 kg | J5: 2,8 kg | K5: 2,8 kg | L5: 2,8 kg (6,2 lb) | M5: 2,8 kg (6,2 lb) | N5: 2,8 kg (6,2 lb) | O5: 2.8 kg | P5: 2.8 kg (6.2 lb) | Q5: 2,8 kg | R5: 2,8 kg | S5: 2,8 kg (6,2 lb) | T5: 2,8 kg | U5: 2.8 kg | V5: 2.8 kg | W5: 6.2 lb (2.8 kg) | X5: 2.8千克（6.2磅） | Y5: 6,2 libry (2,8 kg) | Z5: 2,8 kg | AA5: 2,8 kg | AB5: 2,8 kg | AC5: 2,8 kg | AD5: 2,8 kg (6,2 lb)
A6: fet-feature-weight-ray | B6: 4.29 lbs (1.95 kg) | C6: 4.29 lbs (1.95 kg) | D6: 4.29 lb (1.95 kg) | E6: 4.29 lb (1.95 kg) | F6: 1,95 kg | G6: 1,95 kg | H6: 1,95 kg | I6: 1,95 kg | J6: 1,95 kg | K6: 1,95 kg | L6: 1,95 kg (4,29 lb) | M6: 1,95 kg (4,29 lb) | N6: 1,95 kg (4,29 lb) | O6: 1.95 kg | P6: 1.95 kg (4.29 lb) | Q6: 1,95 kg | R6: 1,95 kg | S6: 1,95 kg (4,29 lb) | T6: 1,95 kg | U6: 1.95 kg | V6: 1.95 kg | W6: 4.29 lb (1.95 kg) | X6: 1.95千克（4.29磅） | Y6: 4,29 libry (1,95 kg) | Z6: 1,95 kg | AA6: 1,95 kg | AB6: 1,95 kg | AC6: 1,95 kg | AD6: 1,95 kg (4,29 lb)
A7: fet-feature-weight-sub | C7: 29 lbs (13.15 kg) | D7: 29 lb (13.15 kg) | E7: 29 lb (13.15 kg) | F7: 13,15 kg | G7: 13,15 kg | H7: 13,15 kg | I7: 13,15 kg | J7: 13,15 kg | K7: 13,15 kg | L7: 13,15 kg (29 lb) | M7: 13,15 kg (29 lb) | N7: 13,15 kg (29 lb) | O7: 13.15 kg | P7: 13.15 kg (29 lb) | Q7: 13,15 kg | R7: 13,15 kg | S7: 13,15 kg (29 lb) | T7: 13,15 kg | U7: 13.15 kg | V7: 13.15 kg | W7: 29 lb (13.15 kg) | X7: 13.15千克（29磅） | Y7: 29 liber (13,15 kg) | Z7: 13,15 kg | AA7: 13,15 kg | AB7: 13,15 kg | AC7: 13,15 kg | AD7: 13,15 kg (29 lb)
A8: fet-feature-weight-gravity | B8: 14 lbs (6.35 kg) | C8: 14 lbs (6.35 kg) | D8: 14 lbs (6.35 kg) | E8: 14 lb (6.35 kg) | F8: 6,35 kg | G8: 6,35 kg | H8: 6,35 kg | I8: 6,35 kg | J8: 6,35 kg | K8: 6,35 kg | L8: 6,35 kg (14 lb) | M8: 6,35 kg (14 lb) | N8: 6,35 kg (14 lb) | O8: 6.35 kg | P8: 6.35 kg (14 lb) | Q8: 6,35 kg | R8: 6,35 kg | S8: 6,35 kg (14 lb) | T8: 6,35 kg | U8: 6.35 kg | V8: 6.35 kg | W8: 14 lb (6.35 kg) | X8: 6.35千克（14磅） | Y8: 14 liber (6,35 kg) | Z8: 6,35 kg | AA8: 6,35 kg | AB8: 6,35 kg | AC8: 6,35 kg | AD8: 6.35 kg (14 lb)
A9: fet-feature-weight-optimo1 | B9: 4.44 lbs (2.02 kg) | C9: 4.44 lbs (2.02 kg) | D9: 4.44 lb (2.02 kg) | E9: 4.44 lb (2.02 kg) | F9: 2,02 kg | G9: 2,02 kg | H9: 2,02 kg | I9: 2,02 kg | J9: 2,02 kg | K9: 2,02 kg | L9: 2,02 kg (4,44 lb) | M9: 2,02 kg (4,44 lb) | N9: 2,02 kg (4,44 lb) | O9: 2.02 kg | P9: 2.02 kg (4.44 lb) | Q9: 2,02 kg | R9: 2,02 kg | S9: 2,02 kg (4,44 lb) | T9: 2,02 kg | U9: 2.02 kg | V9: 2.02 kg | W9: 4.44 lb (2.02 kg) | X9: 2.02千克（4.44磅） | Y9: 4,44 libry (2,02 kg) | Z9: 2,02 kg | AA9: 2,02 kg | AB9: 2,02 kg | AC9: 2,02 kg | AD9: 2,02 kg (4,44 lb)
A10: fet-feature-weight-optimo2 | B10: 9.85 lbs (4.47 kg) | C10: 9.85 lbs (4.47 kg) | D10: 9.85 lb (4.47 kg) | E10: 9.85 lb (4.47 kg) | F10: 4,47 kg | G10: 4,47 kg | H10: 4,47 kg | I10: 4,47 kg | J10: 4,47 kg | K10: 4,47 kg | L10: 4,47 kg (9,85 lb) | M10: 4,47 kg (9,85 lb) | N10: 4,47 kg (9,85 lb) | O10: 4.47 kg | P10: 4.47 kg (9.85 lb) | Q10: 4,47 kg | R10: 4,47 kg | S10: 4,47 kg (9,85 lb) | T10: 4,47 kg | U10: 4.47 kg | V10: 4.47 kg | W10: 9.85 lb (4.47 kg) | X10: 4.47千克（9.85磅） | Y10: 9,85 libry (4,47 kg) | Z10: 4,47 kg | AA10: 4,47 kg | AB10: 4,47 kg | AC10: 4,47 kg | AD10: 4,47 kg (9,85 lb)
A11: fet-feature-weight-five | B11: 14 lbs (6.36 kg) | C11: 14 lbs (6.36 kg) | D11: 14 lb (6.36 kg) | E11: 14 lb (6.36 kg) | F11: 6,36 kg | G11: 6,36 kg | H11: 6,36 kg | I11: 6,36 kg | J11: 6,36 kg | K11: 6,36 kg | L11: 6,36 kg (14 lb) | M11: 6,36 kg (14 lb) | N11: 6,36 kg (14 lb) | O11: 6.36 kg | P11: 6.36 kg (14 lb) | Q11: 6,36 kg | R11: 6,36 kg | S11: 6,36 kg (14 lb) | T11: 6,36 kg | U11: 6.36 kg | V11: 6.36 kg | W11: 14 lb (6.36 kg) | X11: 6.36千克（14磅） | Y11: 14 liber (6,36 kg) | Z11: 6,36 kg | AA11: 6,36 kg | AB11: 6,36 kg | AC11: 6,36 kg | AD11: 6,36 kg (14 lb)
A12: fet-feature-weight-move | C12: 14 lbs (6.36 kg) | D12: 14 lb (6.36 kg) | E12: 14 lb (6.36 kg) | F12: 6,36 kg | G12: 6,36 kg | H12: 6,36 kg | I12: 6,36 kg | J12: 6,36 kg | K12: 6,36 kg | L12: 6,36 kg (14 lb) | M12: 6,36 kg (14 lb) | N12: 6,36 kg (14 lb) | O12: 6.36 kg | P12: 6.36 kg (14 lb) | Q12: 6,36 kg | R12: 6,36 kg | S12: 6,36 kg (14 lb) | T12: 6,36 kg | U12: 6.36 kg | V12: 6.36 kg | W12: 14 lb (6.36 kg) | X12: 6.36千克（14磅） | Y12: 14 liber (6,36 kg) | Z12: 6,36 kg | AA12: 6,36 kg | AB12: 6,36 kg | AC12: 6,36 kg | AD12: 6,36 kg (14 lb)
A13: fet-feature-weight-prima | B13: 6.61 lbs (3 kg) | C13: 6.61 lbs (3 kg) | D13: 6.61 lb (3 kg) | E13: 6.61 lb (3 kg) | F13: 3 kg | G13: 3 kg | H13: 3 kg | I13: 3,0 kg | J13: 3,0 kg | K13: 3,0 kg | L13: 3 kg (6,61 lb) | M13: 3 kg (6,61 lb) | N13: 3 kg (6,61 lb) | O13: 3 kg | P13: 3 kg (6.61 lb) | Q13: 3 kg | R13: 3 kg | S13: 3 kg (6,61 lb) | T13: 3 kg | U13: 3 kg | V13: 3 kg | W13: 6.61 lb (3 kg) | X13: 3千克（6.61磅） | Y13: 6,61 libry (3 kg) | Z13: 3 kg | AA13: 3 kg | AB13: 3 kg | AC13: 3,0 kg | AD13: 3 kg (6,61 lb)
A14: fet-feature-weight-roam | C14: 0.95 lbs (0.43 kg) | D14: 0.95 lb (0.43 kg) | E14: 0.95 lb (0.43 kg) | F14: 0,43 kg | G14: 0,43 kg | H14: 0,43 kg | I14: 0,43 kg | J14: 0,43 kg | K14: 0,43 kg | L14: 0,43 kg (0,95 lb) | M14: 0,43 kg (0,95 lb) | N14: 0,43 kg (0,95 lb) | O14: 0.43 kg | P14: 0.43 kg (0.95 lb) | Q14: 0,43 kg | R14: 0,43 kg | S14: 0,43 kg (0,95 lb) | T14: 0,43 kg | U14: 0.43 kg | V14: 0.43 kg | W14: 0.95 lb (0.43 kg) | X14: 0.43千克（0.95磅） | Y14: 0,95 libry (0,43 kg) | Z14: 0,43 kg | AA14: 0,43 kg | AB14: 0,43 kg | AC14: 0,43 kg | AD14: 0,43 kg (0,95 lb)
A15: fet-feature-weight-roamsl | C15: 0.95 lbs (0.43 kg) | D15: 0.95 lb (0.43 kg) | E15: 0.95 lb (0.43 kg) | F15: 0,43 kg | G15: 0,43 kg | H15: 0,43 kg | I15: 0,43 kg | J15: 0,43 kg | K15: 0,43 kg | L15: 0,43 kg (0,95 lb) | M15: 0,43 kg (0,95 lb) | N15: 0,43 kg (0,95 lb) | O15: 0.43 kg | P15: 0.43 kg (0.95 lb) | Q15: 0,43 kg | R15: 0,43 kg | S15: 0,43 kg (0,95 lb) | T15: 0,43 kg | U15: 0.43 kg | V15: 0.43 kg | W15: 0.95 lb (0.43 kg) | X15: 0.43千克（0.95磅） | Y15: 0,95 libry (0,43 kg) | Z15: 0,43 kg | AA15: 0,43 kg | AB15: 0,43 kg | AC15: 0,43 kg | AD15: 0,43 kg (0,95 lb)
A16: fet-feature-weight-roam2 | B16: 0.95 lbs (0.43 kg) | C16: 0.95 lbs (0.43 kg) | D16: 0.95 lb (0.43 kg) | E16: 0.95 lb (0.43 kg) | F16: 0,43 kg | G16: 0,43 kg | H16: 0,43 kg | I16: 0,43 kg | J16: 0,43 kg | K16: 0,43 kg | L16: 0,43 kg (0,95 lb) | M16: 0,43 kg (0,95 lb) | N16: 0,43 kg (0,95 lb) | O16: 0.43 kg | P16: 0.43 kg (0.95 lb) | Q16: 0,43 kg | R16: 0,43 kg | S16: 0,43 kg (0,95 lb) | T16: 0,43 kg | U16: 0.43 kg | V16: 0.43 kg | W16: 0.95 lb (0.43 kg) | X16: 0.43千克（0.95磅） | Y16: 0,95 libry (0,43 kg) | Z16: 0,43 kg | AA16: 0,43 kg | AB16: 0,43 kg | AC16: 0,43 kg | AD16: 0,43 kg (0,95 lb)
A17: fet-feature-weight-duke | B17: 11.11 oz (315 g) | C17: 11.11 oz (315 g) | D17: 11.11 oz (315 g) | E17: 11.11 oz (315 g) | F17: 315 g | G17: 315 g | H17: 315 g | I17: 315 g | J17: 315 g | K17: 315 g | L17: 315 g (11,11 oz) | M17: 315 g (11,11 oz) | N17: 315 g (11,11 oz) | O17: 315 g | P17: 315 g (11.11 oz) | Q17: 315 g | R17: 315 g | S17: 315 g (11,11 oz) | T17: 315 g | U17: 315 g | V17: 315 g | W17: 11.11 oz (315 g) | X17: 315克（11.11盎司） | Y17: 11,11 libry (315 g) | Z17: 315 g | AA17: 315 g | AB17: 315 g | AC17: 315 g | AD17: 315 g (11,11 oz)
A18: fet-feature-weight-amp | C18: 4.63 lbs (2.1 kg) | D18: 4.63 lbs (2.1 kg) | E18: 4.63 lbs (2.1 kg) | F18: 2.1 kg | G18: 2.1 kg | H18: 2.1 kg | I18: 2,1 kg | J18: 2,1 kg | K18: 2,1 kg | L18: 2.1 kg (4,63 lb) | M18: 2.1 kg (4,63 lb) | N18: 2.1 kg (4,63 lb) | O18: 2.1 kg | P18: 2.1 kg (4.63 lb) | Q18: 2.1 kg | R18: 2.1 kg | S18: 2.1 kg (4.63 lb) | T18: 2.1 kg | U18: 2.1 kg | V18: 2.1 kg | W18: 4.63 lbs (2.1 kg) | X18: 2.1千克（4.63磅） | Y18: 4,63 libry (2.1 kg) | Z18: 2.1 kg | AA18: 2.1 kg | AB18: 2.1 kg | AC18: 2,1 kg | AD18: 2.1 kg (4.63 lb)
A19: fet-name-arc | B19: Arc | C19: Arc | D19: Arc | E19: Arc | F19: Arc | G19: Arc | H19: Arc | I19: Sonos Arc | J19: Sonos Arc | K19: Sonos Arc | L19: Arc | M19: Arc | N19: Arc | O19: Sonos Arc | P19: Arc | Q19: Arc | R19: Arc | S19: Arc | T19: Arc | U19: Arc | V19: Arc | W19: Arc | X19: Arc | Y19: Arc | Z19: Arc | AA19: Arc | AB19: Arc | AC19: Sonos Arc | AD19: Arc
A20: fet-name-beam | B20: Beam | C20: Beam | D20: Beam | E20: Beam | F20: Beam | G20: Beam | H20: Beam | I20: Sonos Beam | J20: Sonos Beam | K20: Sonos Beam | L20: Beam | M20: Beam | N20: Beam | O20: Sonos Beam | P20: Beam | Q20: Beam | R20: Beam | S20: Beam | T20: Beam | U20: Beam | V20: Beam | W20: Beam | X20: Beam | Y20: Beam | Z20: Beam | AA20: Beam | AB20: Beam | AC20: Sonos Beam | AD20: Beam
A21: fet-name-ray | B21: Ray | C21: Ray | D21: Ray | E21: Ray | F21: Ray | G21: Ray | H21: Ray | I21: Sonos Ray | J21: Sonos Ray | K21: Sonos Ray | L21: Ray | M21: Ray | N21: Ray | O21: Sonos Ray | P21: Ray | Q21: Ray | R21: Ray | S21: Ray | T21: Ray | U21: Ray | V21: Ray | W21: Ray | X21: Ray | Y21: Ray | Z21: Ray | AA21: Ray | AB21: Ray | AC21: Sonos Ray | AD21: Ray
A22: fet-name-sub | C22: Sub | D22: Sub | E22: Sub | F22: Sub | G22: Sub | H22: Sub | I22: Sonos Sub | J22: Sonos Sub | K22: Sonos Sub | L22: Sub | M22: Sub | N22: Sub | O22: Sonos Sub | P22: Sub | Q22: Sub | R22: Sub | S22: Sub | T22: Sub | U22: Sub | V22: Sub | W22: Sub | X22: Sub | Y22: Sub | Z22: Sub | AA22: Sub | AB22: Sub | AC22: Sonos Sub | AD22: Sub
A23: fet-name-gravity | B23: Sub Mini | C23: Sub Mini | D23: Sub Mini | E23: Sub Mini | F23: Sub Mini | G23: Sub Mini | H23: Sub Mini | I23: Sonos Sub Mini | J23: Sonos Sub Mini | K23: Sonos Sub Mini | L23: Sub Mini | M23: Sub Mini | N23: Sub Mini | O23: Sonos Sub Mini | P23: Sub Mini | Q23: Sub Mini | R23: Sub Mini | S23: Sub Mini | T23: Sub Mini | U23: Sub Mini | V23: Sub Mini | W23: Sub Mini | X23: Sub Mini | Y23: Sub Mini | Z23: Sub Mini | AA23: Sub Mini | AB23: Sub Mini | AC23: Sonos Sub Mini | AD23: Sub Mini
A24: fet-name-optimo1 | B24: Era 100 | C24: Era 100 | D24: Era 100 | E24: Era 100 | F24: Era 100 | G24: Era 100 | H24: Era 100 | I24: Sonos Era 100 | J24: Sonos Era 100 | K24: Sonos Era 100 | L24: Era 100 | M24: Era 100 | N24: Era 100 | O24: Sonos Era 100 | P24: Era 100 | Q24: Era 100 | R24: Era 100 | S24: Era 100 | T24: Era 100 | U24: Era 100 | V24: Era 100 | W24: Era 100 | X24: Era 100 | Y24: Era 100 | Z24: Era 100 | AA24: Era 100 | AB24: Era 100 | AC24: Sonos Era 100 | AD24: Era 100
A25: fet-name-optimo2 | B25: Era 300 | C25: Era 300 | D25: Era 300 | E25: Era 300 | F25: Era 300 | G25: Era 300 | H25: Era 300 | I25: Sonos Era 300 | J25: Sonos Era 300 | K25: Sonos Era 300 | L25: Era 300 | M25: Era 300 | N25: Era 300 | O25: Sonos Era 300 | P25: Era 300 | Q25: Era 300 | R25: Era 300 | S25: Era 300 | T25: Era 300 | U25: Era 300 | V25: Era 300 | W25: Era 300 | X25: Era 300 | Y25: Era 300 | Z25: Era 300 | AA25: Era 300 | AB25: Era 300 | AC25: Sonos Era 300 | AD25: Era 300
A26: fet-name-five | B26: Five | C26: Five | D26: Five | E26: Five | F26: Five | G26: Five | H26: Five | I26: Sonos Five | J26: Sonos Five | K26: Sonos Five | L26: Five | M26: Five | N26: Five | O26: Sonos Five | P26: Five | Q26: Five | R26: Five | S26: Five | T26: Five | U26: Five | V26: Five | W26: Five | X26: Five | Y26: Five | Z26: Five | AA26: Five | AB26: Five | AC26: Sonos Five | AD26: Five
A27: fet-name-roam | C27: Roam | D27: Roam | E27: Roam | F27: Roam | G27: Roam | H27: Roam | I27: Sonos Roam | J27: Sonos Roam | K27: Sonos Roam | L27: Roam | M27: Roam | N27: Roam | O27: Sonos Roam | P27: Roam | Q27: Roam | R27: Roam | S27: Roam | T27: Roam | U27: Roam | V27: Roam | W27: Roam | X27: Roam | Y27: Roam | Z27: Roam | AA27: Roam | AB27: Roam | AC27: Sonos Roam | AD27: Roam
A28: fet-name-roam2 | B28: Roam 2 | C28: Roam 2 | D28: Roam 2 | E28: Roam 2 | F28: Roam 2 | G28: Roam 2 | H28: Roam 2 | I28: Sonos Roam 2 | J28: Sonos Roam 2 | K28: Sonos Roam 2 | L28: Roam 2 | M28: Roam 2 | N28: Roam 2 | O28: Sonos Roam 2 | P28: Roam 2 | Q28: Roam 2 | R28: Roam 2 | S28: Roam 2 | T28: Roam 2 | U28: Roam 2 | V28: Roam 2 | W28: Roam 2 | X28: Roam 2 | Y28: Roam 2 | Z28: Roam 2 | AA28: Roam 2 | AB28: Roam 2 | AC28: Sonos Roam 2 | AD28: Roam 2
A29: fet-name-roamsl | C29: Roam SL | D29: Roam SL | E29: Roam SL | F29: Roam SL | G29: Roam SL | H29: Roam SL | I29: Sonos Roam SL | J29: Sonos Roam SL | K29: Sonos Roam SL | L29: Roam SL | M29: Roam SL | N29: Roam SL | O29: Sonos Roam SL | P29: Roam SL | Q29: Roam SL | R29: Roam SL | S29: Roam SL | T29: Roam SL | U29: Roam SL | V29: Roam SL | W29: Roam SL | X29: Roam SL | Y29: Roam SL | Z29: Roam SL | AA29: Roam SL | AB29: Roam SL | AC29: Sonos Roam SL | AD29: Roam SL
A30: fet-name-duke | B30: Sonos Ace | C30: Sonos Ace | D30: Sonos Ace | E30: Sonos Ace | F30: Sonos Ace | G30: Sonos Ace | H30: Sonos Ace | I30: Sonos Ace | J30: Sonos Ace | K30: Sonos Ace | L30: Sonos Ace | M30: Sonos Ace | N30: Sonos Ace | O30: Sonos Ace | P30: Sonos Ace | Q30: Sonos Ace | R30: Sonos Ace | S30: Sonos Ace | T30: Sonos Ace | U30: Sonos Ace | V30: Sonos Ace | W30: Sonos Ace | X30: Sonos Ace | Y30: Sonos Ace | Z30: Sonos Ace | AA30: Sonos Ace | AB30: Sonos Ace | AC30: Sonos Ace | AD30: Sonos Ace
A31: fet-name-move | C31: Move | D31: Move | E31: Move | F31: Move | G31: Move | H31: Move | I31: Sonos Move | J31: Sonos Move | K31: Sonos Move | L31: Move | M31: Move | N31: Move | O31: Sonos Move | P31: Move | Q31: Move | R31: Move | S31: Move | T31: Move | U31: Move | V31: Move | W31: Move | X31: Move | Y31: Move | Z31: Move | AA31: Move | AB31: Move | AC31: Sonos Move | AD31: Move
A32: fet-name-prima | B32: Move 2 | C32: Move 2 | D32: Move 2 | E32: Move 2 | F32: Move 2 | G32: Move 2 | H32: Move 2 | I32: Sonos Move 2 | J32: Sonos Move 2 | K32: Sonos Move 2 | L32: Move 2 | M32: Move 2 | N32: Move 2 | O32: Sonos Move 2 | P32: Move 2 | Q32: Move 2 | R32: Move 2 | S32: Move 2 | T32: Move 2 | U32: Move 2 | V32: Move 2 | W32: Move 2 | X32: Move 2 | Y32: Move 2 | Z32: Move 2 | AA32: Move 2 | AB32: Move 2 | AC32: Sonos Move 2 | AD32: Move 2
A33: fet-name-amp | C33: Amp | D33: Amp | E33: Amp | F33: Amp | G33: Amp | H33: Amp | I33: Sonos Amp | J33: Sonos Amp | K33: Sonos Amp | L33: Amp | M33: Amp | N33: Amp | O33: Sonos Amp | P33: Amp | Q33: Amp | R33: Amp | S33: Amp | T33: Amp | U33: Amp | V33: Amp | W33: Amp | X33: Amp | Y33: Amp | Z33: Amp | AA33: Amp | AB33: Amp | AC33: Sonos Amp | AD33: Amp
A34: fet-badge-dolby-atmos | B34: Dolby Atmos | C34: Dolby Atmos | D34: Dolby Atmos | E34: Dolby Atmos | F34: Dolby Atmos | G34: Dolby Atmos | H34: Dolby Atmos | I34: Dolby Atmos | J34: Dolby Atmos | K34: Dolby Atmos | L34: Dolby Atmos | M34: Dolby Atmos | N34: Dolby Atmos | O34: Dolby Atmos（ドルビーアトモス） | P34: Dolby Atmos | Q34: Dolby Atmos | R34: Dolby Atmos | S34: Dolby Atmos | T34: Dolby Atmos | U34: Dolby Atmos | V34: Dolby Atmos | W34: Dolby Atmos | X34: 杜比全景声 | Y34: Dolby Atmos | Z34: Dolby Atmos | AA34: Dolby Atmos | AB34: Dolby Atmos | AC34: Dolby Atmos | AD34: Dolby Atmos
A35: fet-badge-dolby-head-tracking | C35: Dolby head tracking | D35: Dolby head tracking | E35: Dolby head tracking | F35: Dynamisk hovedsporing | G35: Dolby Head Tracking | H35: Dolby Head Tracking | I35: Suivi dynamique des mouvements de la tête | J35: Suivi dynamique des mouvements de la tête | K35: Suivi dynamique des mouvements de la tête | L35: Suivi dynamique de la tête | M35: Rilevamento dinamico della posizione della testa | N35: Rilevamento dinamico della posizione della testa | O35: Dolbyヘッドトラッキング | P35: Rastreo de cabeza Dolby | Q35: Dolby Head Tracking | R35: Dynamisk hodesporing | S35: Seguimiento de la cabeza Dolby | T35: Dynamisk huvudspårning | U35: Dolby head tracking | V35: Dolby head tracking | W35: Dolby head tracking | X35: 杜比头部追踪 | Y35: Dynamické sledování hlavy | Z35: Dolbyn pään asennon seuranta | AA35: Dynamiczne śledzenie ruchu głowy | AB35: Dolby Head Tracking | AC35: Suivi dynamique des mouvements de la tête | AD35: Rastreo de cabeza Dolby
A36: fet-badge-spatial-audio-with-dynamic-head-tracking-1 | B36: Spatial audio with dynamic head tracking¹ | C36: Spatial audio with dynamic head tracking¹ | D36: Spatial audio with dynamic head tracking¹ | E36: Spatial audio with dynamic head tracking¹ | F36: Rumlig lyd med dynamisk hovedsporing¹ | G36: 3D-Audio mit dynamischem Head Tracking¹ | H36: 3D-Audio mit dynamischem Head Tracking¹ | I36: Audio spatial avec suivi dynamique des mouvements de la tête¹ | J36: Audio spatial avec suivi dynamique des mouvements de la tête¹ | K36: Audio spatial avec suivi dynamique des mouvements de la tête¹ | L36: Audio spatial avec suivi dynamique de la tête¹ | M36: Audio spaziale con rilevamento dinamico della posizione della testa¹ | N36: Audio spaziale con rilevamento dinamico della posizione della testa¹ | O36: 空間オーディオとダイナミックヘッドトラッキング¹ | P36: Audio espacial con seguimiento dinámico de la cabeza¹ | Q36: Ruimtelijke audio met dynamische hoofdtracking | R36: Romtilpasset lyd med dynamisk hodesporing¹ | S36: Audio espacial con seguimiento dinámico de la cabeza¹ | T36: Rymligt ljud med dynamisk huvudspårning¹ | U36: Spatial audio with dynamic head tracking¹ | V36: Spatial audio with dynamic head tracking¹ | W36: Spatial audio with dynamic head tracking¹ | X36: 支持动态头部追踪的空间音频¹ | Y36: Prostorový zvuk s dynamickým sledováním hlavy¹ | Z36: Tilaääni dynaamisella pään asennon seurannalla¹ | AA36: Dźwięk przestrzenny z dynamicznym śledzeniem ruchu głowy¹ | AB36: 3D-Audio mit dynamischem Head Tracking¹ | AC36: Audio spatial avec suivi dynamique des mouvements de la tête¹ | AD36: Audio espacial con seguimiento dinámico de la cabeza1
A37: fet-badge-lossless-audio-2 | B37: Lossless audio² | C37: Lossless audio² | D37: Lossless audio² | E37: Lossless audio² | F37: Tabsfri lyd² | G37: Verlustfreies Audio² | H37: Verlustfreies Audio² | I37: Contenus audio sans perte² | J37: Contenus audio sans perte² | K37: Contenus audio sans perte² | L37: Audio sans perte² | M37: Audio lossless² | N37: Audio lossless² | O37: ロスレスオーディオ² | P37: Audio lossless² | Q37: Lossless audio² | R37: Tapsfri lyd² | S37: Sonido sin pérdidas² | T37: Losslessljud² | U37: Lossless audio² | V37: Lossless audio² | W37: Lossless audio² | X37: 无损音频² | Y37: Bezztrátový zvuk² | Z37: Häviötön ääni² | AA37: Dźwięk bezstratny² | AB37: Verlustfreies Audio² | AC37: Contenus audio sans perte² | AD37: Audio lossless²
A38: fet-badge-enhanced-call-clarity | B38: Enhanced call clarity | C38: Enhanced call clarity | D38: Enhanced call clarity | E38: Enhanced call clarity | F38: Tydeligere opkald | G38: Verbesserte Sprachqualität | H38: Verbesserte Sprachqualität | I38: Un son encore plus clair pour les appels | J38: Un son encore plus clair pour les appels | K38: Un son encore plus clair pour les appels | L38: Clarté accrue des appels | M38: Ottimizzazione della nitidezza delle chiamate | N38: Ottimizzazione della nitidezza delle chiamate | O38: より明瞭な音声 | P38: Nitidez de llamada mejorada | Q38: Duidelijkere telefoongesprekken | R38: Økt anropsklarhet | S38: Mejor calidad de las llamadas | T38: Ökad klarhet för samtal | U38: Enhanced call clarity | V38: Enhanced call clarity | W38: Enhanced call clarity | X38: 增强通话清晰度 | Y38: Zvýšená srozumitelnost hovorů | Z38: Kehittyneempi puhelun selkeys | AA38: Większa wyrazistość połączeń telefonicznych | AB38: Verbesserte Sprachqualität | AC38: Un son encore plus clair pour les appels | AD38: Nitidez de llamada mejorada
A39: fet-badge-active-noise-cancellation-capitalized | C39: Active Noise Cancellation | D39: Active Noise Cancellation | E39: Active Noise Cancellation | F39: Aktiv støjreduktion | G39: Aktive Geräuschunterdrückung | H39: Aktive Geräuschunterdrückung | I39: Réduction active du bruit | J39: Réduction active du bruit | K39: Réduction active du bruit | L39: Annulation active des bruits | M39: Cancellazione attiva del rumore | N39: Cancellazione attiva del rumore | O39: ノイズキャンセリング機能 | P39: Cancelación activa de ruido | Q39: Actieve ruisonderdrukking | R39: Aktiv støykansellering | S39: Cancelación activa de ruido | T39: Aktiv brusreducering | U39: Active Noise Cancellation | V39: Active Noise Cancellation | W39: Active Noise Cancellation | X39: 主动消噪 | Y39: Aktivní potlačení hluku | Z39: Aktiivinen melunvaimennus | AA39: Aktywne tłumienie hałasu | AB39: Aktive Geräuschunterdrückung | AC39: Réduction active du bruit | AD39: Cancelación activa de ruido
A40: fet-badge-active-noise-cancellation | B40: Active Noise Cancellation | C40: Active Noise Cancellation | D40: Active Noise Cancellation | E40: Active Noise Cancellation | F40: Aktiv støjreduktion | G40: Aktive Geräuschunterdrückung | H40: Aktive Geräuschunterdrückung | I40: Réduction active du bruit | J40: Réduction active du bruit | K40: Réduction active du bruit | L40: Annulation active des bruits | M40: Cancellazione attiva del rumore | N40: Cancellazione attiva del rumore | O40: ノイズキャンセリング機能 | P40: Cancelación activa de ruido | Q40: Actieve ruisonderdrukking | R40: Aktiv støykansellering | S40: Cancelación activa de ruido | T40: Aktiv brusreducering | U40: Active Noise Cancellation | V40: Active Noise Cancellation | W40: Active Noise Cancellation | X40: 主动消噪 | Y40: Aktivní potlačení hluku | Z40: Aktiivinen melunvaimennus | AA40: Aktywne tłumienie hałasu | AB40: Aktive Geräuschunterdrückung | AC40: Réduction active du bruit | AD40: Cancelación activa de ruido
...

Sheet Translation_Lasso_Release
A1: Key | B1: Description | C1: en-US | D1: en-CA | E1: en-GB | F1: da-DK | G1: de-DE | H1: de-CH | I1: fr-FR | J1: fr-CH | K1: fr-BE | L1: fr-CA | M1: it-IT | N1: it-CH | O1: ja-JP | P1: es-MX | Q1: nl-NL | R1: nb-NO | S1: es-ES | T1: sv-SE | U1: en-AU | V1: en-NZ | W1: en-RW | X1: zh-CN | Y1: cs-CZ | Z1: fi-FI | AA1: pl-PL | AB1: de-LU | AC1: fr-LU | AD1: es-CO
A2: LASSO
A3: fet-badge-6x | C3: 6x
A4: fet-badge-7x | C4: 7x
A5: fet-badge-15x | C5: 15x
A6: LOTUS
A7: fet-feature-trueplay-sub4 | C7: This software measures the acoustics of the room then fine-tunes your Sonos system.
A8: MISSING & DIFFERENCE

Sheet DIFF
A1: FIGMA | B1: SHEETS | C1: KEY | D1: TRANSLATION
A2: $179 | C2: {=IFERROR(INDEX('Duke release copy DEV'!A:A, MATCH(B2, 'Duke release copy DEV'!C:C, 0)), "")} | D2: {=IFERROR(INDEX('Duke release copy DEV'!X:X, MATCH(C2, 'Duke release copy DEV'!A:A, 0)), "")}
A3: $249 | C3: {=IFERROR(INDEX('Duke release copy DEV'!A:A, MATCH(B3, 'Duke release copy DEV'!C:C, 0)), "")} | D3: {=IFERROR(INDEX('Duke release copy DEV'!X:X, MATCH(C3, 'Duke release copy DEV'!A:A, 0)), "")}
A4: $279 | C4: {=IFERROR(INDEX('Duke release copy DEV'!A:A, MATCH(B4, 'Duke release copy DEV'!C:C, 0)), "")} | D4: {=IFERROR(INDEX('Duke release copy DEV'!X:X, MATCH(C4, 'Duke release copy DEV'!A:A, 0)), "")} | E4: In one, but not the other
A5: $429 | C5: {=IFERROR(INDEX('Duke release copy DEV'!A:A, MATCH(B5, 'Duke release copy DEV'!C:C, 0)), "")} | D5: {=IFERROR(INDEX('Duke release copy DEV'!X:X, MATCH(C5, 'Duke release copy DEV'!A:A, 0)), "")} | E5: In both Figma and Sheet
A6: $449 | C6: {=IFERROR(INDEX('Duke release copy DEV'!A:A, MATCH(B6, 'Duke release copy DEV'!C:C, 0)), "")} | D6: {=IFERROR(INDEX('Duke release copy DEV'!X:X, MATCH(C6, 'Duke release copy DEV'!A:A, 0)), "")} | E6: Missing
A7: $499 | C7: {=IFERROR(INDEX('Duke release copy DEV'!A:A, MATCH(B7, 'Duke release copy DEV'!C:C, 0)), "")} | D7: {=IFERROR(INDEX('Duke release copy DEV'!X:X, MATCH(C7, 'Duke release copy DEV'!A:A, 0)), "")}
A8: $549 | C8: {=IFERROR(INDEX('Duke release copy DEV'!A:A, MATCH(B8, 'Duke release copy DEV'!C:C, 0)), "")} | D8: {=IFERROR(INDEX('Duke release copy DEV'!X:X, MATCH(C8, 'Duke release copy DEV'!A:A, 0)), "")}
A9: $799 | C9: {=IFERROR(INDEX('Duke release copy DEV'!A:A, MATCH(B9, 'Duke release copy DEV'!C:C, 0)), "")} | D9: {=IFERROR(INDEX('Duke release copy DEV'!X:X, MATCH(C9, 'Duke release copy DEV'!A:A, 0)), "")}
A10: $899.99 | C10: {=IFERROR(INDEX('Duke release copy DEV'!A:A, MATCH(B10, 'Duke release copy DEV'!C:C, 0)), "")} | D10: {=IFERROR(INDEX('Duke release copy DEV'!X:X, MATCH(C10, 'Duke release copy DEV'!A:A, 0)), "")}
B11: *HDMI eARC connection required. **This is not an indication of a licensed decoder. | C11: {=IFERROR(INDEX('Duke release copy DEV'!A:A, MATCH(B11, 'Duke release copy DEV'!C:C, 0)), "")} | D11: {=IFERROR(INDEX('Duke release copy DEV'!X:X, MATCH(C11, 'Duke release copy DEV'!A:A, 0)), "")}
A12: 0.95 lb (0.43 kg) | B12: 0.95 lb (0.43 kg) | C12: {=IFERROR(INDEX('Duke release copy DEV'!A:A, MATCH(B12, 'Duke release copy DEV'!C:C, 0)), "")} | D12: {=IFERROR(INDEX('Duke release copy DEV'!X:X, MATCH(C12, 'Duke release copy DEV'!A:A, 0)), "")}
A13: 01 | C13: {=IFERROR(INDEX('Duke release copy DEV'!A:A, MATCH(B13, 'Duke release copy DEV'!C:C, 0)), "")} | D13: {=IFERROR(INDEX('Duke release copy DEV'!X:X, MATCH(C13, 'Duke release copy DEV'!A:A, 0)), "")}
A14: 02 | C14: {=IFERROR(INDEX('Duke release copy DEV'!A:A, MATCH(B14, 'Duke release copy DEV'!C:C, 0)), "")} | D14: {=IFERROR(INDEX('Duke release copy DEV'!X:X, MATCH(C14, 'Duke release copy DEV'!A:A, 0)), "")}
A15: 03 | C15: {=IFERROR(INDEX('Duke release copy DEV'!A:A, MATCH(B15, 'Duke release copy DEV'!C:C, 0)), "")} | D15: {=IFERROR(INDEX('Duke release copy DEV'!X:X, MATCH(C15, 'Duke release copy DEV'!A:A, 0)), "")}
A16: 04 | C16: {=IFERROR(INDEX('Duke release copy DEV'!A:A, MATCH(B16, 'Duke release copy DEV'!C:C, 0)), "")} | D16: {=IFERROR(INDEX('Duke release copy DEV'!X:X, MATCH(C16, 'Duke release copy DEV'!A:A, 0)), "")}
A17: 05 | C17: {=IFERROR(INDEX('Duke release copy DEV'!A:A, MATCH(B17, 'Duke release copy DEV'!C:C, 0)), "")} | D17: {=IFERROR(INDEX('Duke release copy DEV'!X:X, MATCH(C17, 'Duke release copy DEV'!A:A, 0)), "")}
A18: 06 | C18: {=IFERROR(INDEX('Duke release copy DEV'!A:A, MATCH(B18, 'Duke release copy DEV'!C:C, 0)), "")} | D18: {=IFERROR(INDEX('Duke release copy DEV'!X:X, MATCH(C18, 'Duke release copy DEV'!A:A, 0)), "")}
A19: 1 GB SDRAM8 GB NV | B19: 1 GB SDRAM8 GB NV | C19: {=IFERROR(INDEX('Duke release copy DEV'!A:A, MATCH(B19, 'Duke release copy DEV'!C:C, 0)), "")} | D19: {=IFERROR(INDEX('Duke release copy DEV'!X:X, MATCH(C19, 'Duke release copy DEV'!A:A, 0)), "")}
A20: 10+ hour battery life | B20: 10+ hour battery life | C20: {=IFERROR(INDEX('Duke release copy DEV'!A:A, MATCH(B20, 'Duke release copy DEV'!C:C, 0)), "")} | D20: {=IFERROR(INDEX('Duke release copy DEV'!X:X, MATCH(C20, 'Duke release copy DEV'!A:A, 0)), "")}
A21: 100-240V 50/60Hz internal power supply | B21: 100-240V 50/60Hz internal power supply | C21: {=IFERROR(INDEX('Duke release copy DEV'!A:A, MATCH(B21, 'Duke release copy DEV'!C:C, 0)), "")} -> fet-feature-voltage-100-240V-50-60Hz | D21: {=IFERROR(INDEX('Duke release copy DEV'!X:X, MATCH(C21, 'Duke release copy DEV'!A:A, 0)), "")} -> 100-240V 50/60Hz内部电源
A22: 11.11 oz (315 g) | B22: 11.11 oz (315 g) | C22: {=IFERROR(INDEX('Duke release copy DEV'!A:A, MATCH(B22, 'Duke release copy DEV'!C:C, 0)), "")} -> fet-feature-weight-duke | D22: {=IFERROR(INDEX('Duke release copy DEV'!X:X, MATCH(C22, 'Duke release copy DEV'!A:A, 0)), "")} -> 315克（11.11盎司）
A23: 13 lb (5.9 kg) | B23: 13 lb (5.9 kg) | C23: {=IFERROR(INDEX('Duke release copy DEV'!A:A, MATCH(B23, 'Duke release copy DEV'!C:C, 0)), "")} | D23: {=IFERROR(INDEX('Duke release copy DEV'!X:X, MATCH(C23, 'Duke release copy DEV'!A:A, 0)), "")}
B24: 13.78 lb (6.25 kg) | C24: {=IFERROR(INDEX('Duke release copy DEV'!A:A, MATCH(B24, 'Duke release copy DEV'!C:C, 0)), "")} | D24: {=IFERROR(INDEX('Duke release copy DEV'!X:X, MATCH(C24, 'Duke release copy DEV'!A:A, 0)), "")}
A25: 14 lb (6.35 kg) | B25: 14 lb (6.35 kg) | C25: {=IFERROR(INDEX('Duke release copy DEV'!A:A, MATCH(B25, 'Duke release copy DEV'!C:C, 0)), "")} | D25: {=IFERROR(INDEX('Duke release copy DEV'!X:X, MATCH(C25, 'Duke release copy DEV'!A:A, 0)), "")}
A26: 14 lb (6.36 kg) | B26: 14 lb (6.36 kg) | C26: {=IFERROR(INDEX('Duke release copy DEV'!A:A, MATCH(B26, 'Duke release copy DEV'!C:C, 0)), "")} | D26: {=IFERROR(INDEX('Duke release copy DEV'!X:X, MATCH(C26, 'Duke release copy DEV'!A:A, 0)), "")}
A27: 14°F to 130°F (-10°C to 55°C) | B27: 14°F to 130°F (-10°C to 55°C) | C27: {=IFERROR(INDEX('Duke release copy DEV'!A:A, MATCH(B27, 'Duke release copy DEV'!C:C, 0)), "")} -> fet-feature-operating-temperature-prima | D27: {=IFERROR(INDEX('Duke release copy DEV'!X:X, MATCH(C27, 'Duke release copy DEV'!A:A, 0)), "")} -> -10°C到55°C （14°F到130°F）
A28: 15x | C28: {=IFERROR(INDEX('Duke release copy DEV'!A:A, MATCH(B28, 'Duke release copy DEV'!C:C, 0)), "")} | D28: {=IFERROR(INDEX('Duke release copy DEV'!X:X, MATCH(C28, 'Duke release copy DEV'!A:A, 0)), "")}
B29: 16 GB SDRAM 8GB NV | C29: {=IFERROR(INDEX('Duke release copy DEV'!A:A, MATCH(B29, 'Duke release copy DEV'!C:C, 0)), "")} -> fet-feature-memory-16-gb-sdram-8gb-nv | D29: {=IFERROR(INDEX('Duke release copy DEV'!X:X, MATCH(C29, 'Duke release copy DEV'!A:A, 0)), "")} -> 16 GB SDRAM 8GB NV
A30: 16 GB SDRAM 8GB NV | C30: {=IFERROR(INDEX('Duke release copy DEV'!A:A, MATCH(B30, 'Duke release copy DEV'!C:C, 0)), "")} | D30: {=IFERROR(INDEX('Duke release copy DEV'!X:X, MATCH(C30, 'Duke release copy DEV'!A:A, 0)), "")}
B31: 18Wh battery provides up to 10 hours of continuous playback on a single charge at moderate volumes. | C31: {=IFERROR(INDEX('Duke release copy DEV'!A:A, MATCH(B31, 'Duke release copy DEV'!C:C, 0)), "")} -> fet-feature-battery-roam2 | D31: {=IFERROR(INDEX('Duke release copy DEV'!X:X, MATCH(C31, 'Duke release copy DEV'!A:A, 0)), "")} -> 18Wh电池在中等音量下一次充电即可享受长达10小时连续播放。
A32: 18Wh battery provides up to 10 hours of continuous playback on a single charge. | B32: 18Wh battery provides up to 10 hours of continuous playback on a single charge. | C32: {=IFERROR(INDEX('Duke release copy DEV'!A:A, MATCH(B32, 'Duke release copy DEV'!C:C, 0)), "")} | D32: {=IFERROR(INDEX('Duke release copy DEV'!X:X, MATCH(C32, 'Duke release copy DEV'!A:A, 0)), "")}
A33: 1GB SDRAM 4GB NV | B33: 1GB SDRAM 4GB NV | C33: {=IFERROR(INDEX('Duke release copy DEV'!A:A, MATCH(B33, 'Duke release copy DEV'!C:C, 0)), "")} -> fet-feature-memory-1gb-sdram-4gb-nv | D33: {=IFERROR(INDEX('Duke release copy DEV'!X:X, MATCH(C33, 'Duke release copy DEV'!A:A, 0)), "")} -> 1GB SDRAM 4GB NV
A34: 1x | C34: {=IFERROR(INDEX('Duke release copy DEV'!A:A, MATCH(B34, 'Duke release copy DEV'!C:C, 0)), "")} | D34: {=IFERROR(INDEX('Duke release copy DEV'!X:X, MATCH(C34, 'Duke release copy DEV'!A:A, 0)), "")}
A35: 24 hour battery life | B35: 24 hour battery life | C35: {=IFERROR(INDEX('Duke release copy DEV'!A:A, MATCH(B35, 'Duke release copy DEV'!C:C, 0)), "")} -> fet-badge-battery-life-24 | D35: {=IFERROR(INDEX('Duke release copy DEV'!X:X, MATCH(C35, 'Duke release copy DEV'!A:A, 0)), "")} -> 24小时电池续航时间
A36: 256 MB SDRAM 256 MB NAND Flash | B36: 256 MB SDRAM 256 MB NAND Flash | C36: {=IFERROR(INDEX('Duke release copy DEV'!A:A, MATCH(B36, 'Duke release copy DEV'!C:C, 0)), "")} -> fet-feature-memory-256-mb-sdram-256-mb-nand-flash | D36: {=IFERROR(INDEX('Duke release copy DEV'!X:X, MATCH(C36, 'Duke release copy DEV'!A:A, 0)), "")} -> 256 MB SDRAM 256 MB NAND Flash
A37: 26 lb (11.79 kg) | B37: 26 lb (11.79 kg) | C37: {=IFERROR(INDEX('Duke release copy DEV'!A:A, MATCH(B37, 'Duke release copy DEV'!C:C, 0)), "")} | D37: {=IFERROR(INDEX('Duke release copy DEV'!X:X, MATCH(C37, 'Duke release copy DEV'!A:A, 0)), "")}
A38: 29 lb (13.15 kg) | B38: 29 lb (13.15 kg) | C38: {=IFERROR(INDEX('Duke release copy DEV'!A:A, MATCH(B38, 'Duke release copy DEV'!C:C, 0)), "")} | D38: {=IFERROR(INDEX('Duke release copy DEV'!X:X, MATCH(C38, 'Duke release copy DEV'!A:A, 0)), "")}
A39: 2x | C39: {=IFERROR(INDEX('Duke release copy DEV'!A:A, MATCH(B39, 'Duke release copy DEV'!C:C, 0)), "")} | D39: {=IFERROR(INDEX('Duke release copy DEV'!X:X, MATCH(C39, 'Duke release copy DEV'!A:A, 0)), "")}
A40: 30 hour battery life | B40: 30 hour battery life | C40: {=IFERROR(INDEX('Duke release copy DEV'!A:A, MATCH(B40, 'Duke release copy DEV'!C:C, 0)), "")} -> fet-badge-battery-life-30 | D40: {=IFERROR(INDEX('Duke release copy DEV'!X:X, MATCH(C40, 'Duke release copy DEV'!A:A, 0)), "")} -> 30小时电池续航时间
...

Sheet VARIABLES
A1: fet-10HourBatteryLife | B1: 10+ hour battery life
A2: fet-24HourBatteryLife | B2: 24 hour battery life
A3: fet-30HourBatteryLife | B3: 30 hour battery life
A4: fet-30HourBatteryLifeUpTo | B4: Battery life up to 30 hours³
A5: fet-40mmDrivers | B5: Custom-designed 40mm dynamic drivers
A6: fet-6InchWoofers | B6: 6” woofers
A7: fet-about-slide1-description | B7: Each speaker is thoughtfully designed from the inside out then fine-tuned by award-winning creators.
A8: fet-about-slide1-title | B8: Hear how sound should sound
A9: fet-about-slide2-description | B9: Stream music and more from all your favorite services and get incredible sound for TV or even vinyl.
A10: fet-about-slide2-title | B10: Play everything you love
A11: fet-about-slide3-description | B11: Mix and match speakers to build the system you want over time. Everything works together over WiFi.
A12: fet-about-slide3-title | B12: Customize your system
... A191: fet-worksWithAppleAndAndroid | B191: Works with Apple and Android

Sheet Mojave and Bambino - 1213
A1: Key | B1: Description | C1: en-US | D1: en-CA | E1: en-GB | F1: da-DK | G1: de-DE | H1: de-CH | I1: fr-FR | J1: fr-CH | K1: fr-BE | L1: fr-CA | M1: it-IT | N1: it-CH | O1: ja-JP | P1: es-MX | Q1: nl-NL | R1: nb-NO | S1: es-ES | T1: sv-SE | U1: en-AU | V1: en-NZ | W1: en-RW | X1: zh-CN | Y1: cs-CZ | Z1: fi-FI | AA1: pl-PL | AB1: de-LU | AC1: fr-LU | AD1: es-CO
A2: fet-header-intro-system-story | C2: Discover how Sonos brings your home together with seamless sound, room to room and beyond.
A3: fet-slide-1-headline-system-story | C3: The power of the Sonos system
A5: fet-feature-dimensions | B5: Learn More / Details & Dimensions | C5: Dimensions | D5: Dimensions | E5: Dimensions | F5: Mål | G5: Abmessungen | H5: Abmessungen | I5: Dimensions | J5: Dimensions | K5: Dimensions | L5: Dimensions | M5: Dimensioni | N5: Dimensioni | O5: 寸法 | P5: Dimensiones | Q5: Afmetingen | R5: Mål | S5: Dimensiones | T5: Mått | U5: Dimensions | V5: Dimensions | W5: Dimensions | X5: 尺寸 | Y5: Rozměry | Z5: Mitat | AA5: Wymiary | AB5: Abmessungen | AC5: Dimensions | AD5: Dimensiones
A6: fet-feature-weight | B6: Learn More / Details & Dimensions | C6: Weight | D6: Weight | E6: Weight | F6: Vægt | G6: Gewicht | H6: Gewicht | I6: Poids | J6: Poids | K6: Poids | L6: Poids | M6: Peso | N6: Peso | O6: 重量 | P6: Peso | Q6: Gewicht | R6: Vekt | S6: Peso | T6: Vikt | U6: Weight | V6: Weight | W6: Weight | X6: 重量 | Y6: Hmotnost | Z6: Paino | AA6: Waga | AB6: Gewicht | AC6: Poids | AD6: Peso
A7: fet-feature-weight-arc | B7: Learn More / Details & Dimensions / Arc | C7: 13.78 lb (6.25 kg) | D7: 13.78 lb (6.25 kg) | E7: 13.78 lb (6.25 kg) | F7: 6,25 kg | G7: 6,25 kg | H7: 6,25 kg | I7: 6,25 kg | J7: 6,25 kg | K7: 6,25 kg | L7: 6,25 kg (13,78 lb) | M7: 6,25 kg (13,78 lb) | N7: 6,25 kg (13,78 lb) | O7: 6.25 kg | P7: 6.25 kg (13.78 lb) | Q7: 6,25 kg | R7: 6,25 kg | S7: 6,25 kg (13,78 lb) | T7: 6,25 kg | U7: 6.25 kg | V7: 6.25 kg | W7: 13.78 lb (6.25 kg) | X7: 6.25千克（13.78磅） | Y7: 13,78 libry (6,25 kg) | Z7: 6,25 kg | AA7: 6,25 kg | AB7: 6,25 kg | AC7: 6,25 kg | AD7: 6,25 kg (13,78 lb)
A8: fet-feature-weight-beam | B8: Learn More / Details & Dimensions / Beam | C8: 6.2 lb (2.8 kg) | D8: 6.2 lb (2.8 kg) | E8: 6.2 lb (2.8 kg) | F8: 2,8 kg | G8: 2,8 kg | H8: 2,8 kg | I8: 2,8 kg | J8: 2,8 kg | K8: 2,8 kg | L8: 2,8 kg (6,2 lb) | M8: 2,8 kg (6,2 lb) | N8: 2,8 kg (6,2 lb) | O8: 2.8 kg | P8: 2.8 kg (6.2 lb) | Q8: 2,8 kg | R8: 2,8 kg | S8: 2,8 kg (6,2 lb) | T8: 2,8 kg | U8: 2.8 kg | V8: 2.8 kg | W8: 6.2 lb (2.8 kg) | X8: 2.8千克（6.2磅） | Y8: 6,2 libry (2,8 kg) | Z8: 2,8 kg | AA8: 2,8 kg | AB8: 2,8 kg | AC8: 2,8 kg | AD8: 2,8 kg (6,2 lb)
A9: fet-feature-weight-ray | B9: Learn More / Details & Dimensions / Ray | C9: 4.29 lb (1.95 kg) | D9: 4.29 lb (1.95 kg) | E9: 4.29 lb (1.95 kg) | F9: 1,95 kg | G9: 1,95 kg | H9: 1,95 kg | I9: 1,95 kg | J9: 1,95 kg | K9: 1,95 kg | L9: 1,95 kg (4,29 lb) | M9: 1,95 kg (4,29 lb) | N9: 1,95 kg (4,29 lb) | O9: 1.95 kg | P9: 1.95 kg (4.29 lb) | Q9: 1,95 kg | R9: 1,95 kg | S9: 1,95 kg (4,29 lb) | T9: 1,95 kg | U9: 1.95 kg | V9: 1.95 kg | W9: 4.29 lb (1.95 kg) | X9: 1.95千克（4.29磅） | Y9: 4,29 libry (1,95 kg) | Z9: 1,95 kg | AA9: 1,95 kg | AB9: 1,95 kg | AC9: 1,95 kg | AD9: 1,95 kg (4,29 lb)
A10: fet-feature-weight-sub | B10: Learn More / Details & Dimensions / Sub | C10: 29 lb (13.15 kg) | D10: 29 lb (13.15 kg) | E10: 29 lb (13.15 kg) | F10: 13,15 kg | G10: 13,15 kg | H10: 13,15 kg | I10: 13,15 kg | J10: 13,15 kg | K10: 13,15 kg | L10: 13,15 kg (29 lb) | M10: 13,15 kg (29 lb) | N10: 13,15 kg (29 lb) | O10: 13.15 kg | P10: 13.15 kg (29 lb) | Q10: 13,15 kg | R10: 13,15 kg | S10: 13,15 kg (29 lb) | T10: 13,15 kg | U10: 13.15 kg | V10: 13.15 kg | W10: 29 lb (13.15 kg) | X10: 13.15千克（29磅） | Y10: 29 liber (13,15 kg) | Z10: 13,15 kg | AA10: 13,15 kg | AB10: 13,15 kg | AC10: 13,15 kg | AD10: 13,15 kg (29 lb)
A11: fet-feature-weight-gravity | B11: Learn More / Tech Specs / Details & Dimensions tab | C11: 14 lb (6.35 kg) | D11: 14 lbs (6.35 kg) | E11: 14 lb (6.35 kg) | F11: 6,35 kg | G11: 6,35 kg | H11: 6,35 kg | I11: 6,35 kg | J11: 6,35 kg | K11: 6,35 kg | L11: 6,35 kg (14 lb) | M11: 6,35 kg (14 lb) | N11: 6,35 kg (14 lb) | O11: 6.35 kg | P11: 6.35 kg (14 lb) | Q11: 6,35 kg | R11: 6,35 kg | S11: 6,35 kg (14 lb) | T11: 6,35 kg | U11: 6.35 kg | V11: 6.35 kg | W11: 14 lb (6.35 kg) | X11: 6.35千克（14磅） | Y11: 14 liber (6,35 kg) | Z11: 6,35 kg | AA11: 6,35 kg | AB11: 6,35 kg | AC11: 6,35 kg | AD11: 6.35 kg (14 lb)
A12: fet-feature-weight-optimo1 | B12: Learn More / Details & Dimensions / Optimo 1 | C12: 4.44 lb (2.02 kg) | D12: 4.44 lb (2.02 kg) | E12: 4.44 lb (2.02 kg) | F12: 2,02 kg | G12: 2,02 kg | H12: 2,02 kg | I12: 2,02 kg | J12: 2,02 kg | K12: 2,02 kg | L12: 2,02 kg (4,44 lb) | M12: 2,02 kg (4,44 lb) | N12: 2,02 kg (4,44 lb) | O12: 2.02 kg | P12: 2.02 kg (4.44 lb) | Q12: 2,02 kg | R12: 2,02 kg | S12: 2,02 kg (4,44 lb) | T12: 2,02 kg | U12: 2.02 kg | V12: 2.02 kg | W12: 4.44 lb (2.02 kg) | X12: 2.02千克（4.44磅） | Y12: 4,44 libry (2,02 kg) | Z12: 2,02 kg | AA12: 2,02 kg | AB12: 2,02 kg | AC12: 2,02 kg | AD12: 2,02 kg (4,44 lb)
A13: fet-feature-weight-optimo2 | B13: Learn More / Details & Dimensions / Optimo 2 | C13: 9.85 lb (4.47 kg) | D13: 9.85 lb (4.47 kg) | E13: 9.85 lb (4.47 kg) | F13: 4,47 kg | G13: 4,47 kg | H13: 4,47 kg | I13: 4,47 kg | J13: 4,47 kg | K13: 4,47 kg | L13: 4,47 kg (9,85 lb) | M13: 4,47 kg (9,85 lb) | N13: 4,47 kg (9,85 lb) | O13: 4.47 kg | P13: 4.47 kg (9.85 lb) | Q13: 4,47 kg | R13: 4,47 kg | S13: 4,47 kg (9,85 lb) | T13: 4,47 kg | U13: 4.47 kg | V13: 4.47 kg | W13: 9.85 lb (4.47 kg) | X13: 4.47千克（9.85磅） | Y13: 9,85 libry (4,47 kg) | Z13: 4,47 kg | AA13: 4,47 kg | AB13: 4,47 kg | AC13: 4,47 kg | AD13: 4,47 kg (9,85 lb)
A14: fet-feature-weight-five | B14: Learn More / Details & Dimensions / Five | C14: 14 lb (6.36 kg) | D14: 14 lb (6.36 kg) | E14: 14 lb (6.36 kg) | F14: 6,36 kg | G14: 6,36 kg | H14: 6,36 kg | I14: 6,36 kg | J14: 6,36 kg | K14: 6,36 kg | L14: 6,36 kg (14 lb) | M14: 6,36 kg (14 lb) | N14: 6,36 kg (14 lb) | O14: 6.36 kg | P14: 6.36 kg (14 lb) | Q14: 6,36 kg | R14: 6,36 kg | S14: 6,36 kg (14 lb) | T14: 6,36 kg | U14: 6.36 kg | V14: 6.36 kg | W14: 14 lb (6.36 kg) | X14: 6.36千克（14磅） | Y14: 14 liber (6,36 kg) | Z14: 6,36 kg | AA14: 6,36 kg | AB14: 6,36 kg | AC14: 6,36 kg | AD14: 6,36 kg (14 lb)
A15: fet-feature-weight-move | B15: Learn More / Details & Dimensions / Move | C15: 14 lb (6.36 kg) | D15: 14 lb (6.36 kg) | E15: 14 lb (6.36 kg) | F15: 6,36 kg | G15: 6,36 kg | H15: 6,36 kg | I15: 6,36 kg | J15: 6,36 kg | K15: 6,36 kg | L15: 6,36 kg (14 lb) | M15: 6,36 kg (14 lb) | N15: 6,36 kg (14 lb) | O15: 6.36 kg | P15: 6.36 kg (14 lb) | Q15: 6,36 kg | R15: 6,36 kg | S15: 6,36 kg (14 lb) | T15: 6,36 kg | U15: 6.36 kg | V15: 6.36 kg | W15: 14 lb (6.36 kg) | X15: 6.36千克（14磅） | Y15: 14 liber (6,36 kg) | Z15: 6,36 kg | AA15: 6,36 kg | AB15: 6,36 kg | AC15: 6,36 kg | AD15: 6,36 kg (14 lb)
A16: fet-feature-weight-prima | B16: Learn More / Details & Dimensions / Prima | C16: 6.61 lb (3 kg) | D16: 6.61 lb (3 kg) | E16: 6.61 lb (3 kg) | F16: 3 kg | G16: 3 kg | H16: 3 kg | I16: 3,0 kg | J16: 3,0 kg | K16: 3,0 kg | L16: 3 kg (6,61 lb) | M16: 3 kg (6,61 lb) | N16: 3 kg (6,61 lb) | O16: 3 kg | P16: 3 kg (6.61 lb) | Q16: 3 kg | R16: 3 kg | S16: 3 kg (6,61 lb) | T16: 3 kg | U16: 3 kg | V16: 3 kg | W16: 6.61 lb (3 kg) | X16: 3千克（6.61磅） | Y16: 6,61 libry (3 kg) | Z16: 3 kg | AA16: 3 kg | AB16: 3 kg | AC16: 3,0 kg | AD16: 3 kg (6,61 lb)
... A18: fet-feature-weight-roamsl | B18: Learn More / Details & Dimensions / RoamSL | C18: 0.95 lb (0.43 kg) | D18: 0.95 lb (0.43 kg) | E18: 0.95 lb (0.43 kg) | F18: 0,43 kg | G18: 0,43 kg | H18: 0,43 kg | I18: 0,43 kg | J18: 0,43 kg | K18: 0,43 kg | L18: 0,43 kg (0,95 lb) | M18: 0,43 kg (0,95 lb) | N18: 0,43 kg (0,95 lb) | O18: 0.43 kg | P18: 0.43 kg (0.95 lb) | Q18: 0,43 kg | R18: 0,43 kg | S18: 0,43 kg (0,95 lb) | T18: 0,43 kg | U18: 0.43 kg | V18: 0.43 kg | W18: 0.95 lb (0.43 kg) | X18: 0.43千克（0.95磅） | Y18: 0,95 libry (0,43 kg) | Z18: 0,43 kg | AA18: 0,43 kg | AB18: 0,43 kg | AC18: 0,43 kg | AD18: 0,43 kg (0,95 lb)
A19: fet-feature-weight-roam2 | C19: 0.95 lb (0.43 kg) | D19: 0.95 lb (0.43 kg) | E19: 0.95 lb (0.43 kg) | F19: 0,43 kg | G19: 0,43 kg | H19: 0,43 kg | I19: 0,43 kg | J19: 0,43 kg | K19: 0,43 kg | L19: 0,43 kg (0,95 lb) | M19: 0,43 kg (0,95 lb) | N19: 0,43 kg (0,95 lb) | O19: 0.43 kg | P19: 0.43 kg (0.95 lb) | Q19: 0,43 kg | R19: 0,43 kg | S19: 0,43 kg (0,95 lb) | T19: 0,43 kg | U19: 0.43 kg | V19: 0.43 kg | W19: 0.95 lb (0.43 kg) | X19: 0.43千克（0.95磅） | Y19: 0,95 libry (0,43 kg) | Z19: 0,43 kg | AA19: 0,43 kg | AB19: 0,43 kg | AC19: 0,43 kg | AD19: 0,43 kg (0,95 lb)
A20: fet-feature-weight-duke | C20: 11.11 oz (315 g) | D20: 11.11 oz (315 g) | E20: 11.11 oz (315 g) | F20: 315 g | G20: 315 g | H20: 315 g | I20: 315 g | J20: 315 g | K20: 315 g | L20: 315 g (11,11 oz) | M20: 315 g (11,11 oz) | N20: 315 g (11,11 oz) | O20: 315 g | P20: 315 g (11.11 oz) | Q20: 315 g | R20: 315 g | S20: 315 g (11,11 oz) | T20: 315 g | U20: 315 g | V20: 315 g | W20: 11.11 oz (315 g) | X20: 315克（11.11盎司） | Y20: 11,11 libry (315 g) | Z20: 315 g | AA20: 315 g | AB20: 315 g | AC20: 315 g | AD20: 315 g (11,11 oz)
A21: fet-feature-weight-amp | B21: Learn More / Details & Dimensions / Amp | C21: 4.63 lbs (2.1 kg) | D21: 4.63 lbs (2.1 kg) | E21: 4.63 lbs (2.1 kg) | F21: 2.1 kg | G21: 2.1 kg | H21: 2.1 kg | I21: 2,1 kg | J21: 2,1 kg | K21: 2,1 kg | L21: 2.1 kg (4,63 lb) | M21: 2.1 kg (4,63 lb) | N21: 2.1 kg (4,63 lb) | O21: 2.1 kg | P21: 2.1 kg (4.63 lb) | Q21: 2.1 kg | R21: 2.1 kg | S21: 2.1 kg (4.63 lb) | T21: 2.1 kg | U21: 2.1 kg | V21: 2.1 kg | W21: 4.63 lbs (2.1 kg) | X21: 2.1千克（4.63磅） | Y21: 4,63 libry (2.1 kg) | Z21: 2.1 kg | AA21: 2.1 kg | AB21: 2.1 kg | AC21: 2,1 kg | AD21: 2.1 kg (4.63 lb)
A22: fet-name-arc | B22: Learn More / Compare & Features | C22: Arc | D22: Arc | E22: Arc | F22: Arc | G22: Arc | H22: Arc | I22: Sonos Arc | J22: Sonos Arc | K22: Sonos Arc | L22: Arc | M22: Arc | N22: Arc | O22: Sonos Arc | P22: Arc | Q22: Arc | R22: Arc | S22: Arc | T22: Arc | U22: Arc | V22: Arc | W22: Arc | X22: Arc | Y22: Arc | Z22: Arc | AA22: Arc | AB22: Arc | AC22: Sonos Arc | AD22: Arc
A23: fet-name-beam | B23: Learn More / Compare & Features | C23: Beam | D23: Beam | E23: Beam | F23: Beam | G23: Beam | H23: Beam | I23: Sonos Beam | J23: Sonos Beam | K23: Sonos Beam | L23: Beam | M23: Beam | N23: Beam | O23: Sonos Beam | P23: Beam | Q23: Beam | R23: Beam | S23: Beam | T23: Beam | U23: Beam | V23: Beam | W23: Beam | X23: Beam | Y23: Beam | Z23: Beam | AA23: Beam | AB23: Beam | AC23: Sonos Beam | AD23: Beam
A24: fet-name-ray | B24: Learn More / Compare & Features | C24: Ray | D24: Ray | E24: Ray | F24: Ray | G24: Ray | H24: Ray | I24: Sonos Ray | J24: Sonos Ray | K24: Sonos Ray | L24: Ray | M24: Ray | N24: Ray | O24: Sonos Ray | P24: Ray | Q24: Ray | R24: Ray | S24: Ray | T24: Ray | U24: Ray | V24: Ray | W24: Ray | X24: Ray | Y24: Ray | Z24: Ray | AA24: Ray | AB24: Ray | AC24: Sonos Ray | AD24: Ray
A25: fet-name-sub | B25: Learn More / Compare & Features | C25: Sub | D25: Sub | E25: Sub | F25: Sub | G25: Sub | H25: Sub | I25: Sonos Sub | J25: Sonos Sub | K25: Sonos Sub | L25: Sub | M25: Sub | N25: Sub | O25: Sonos Sub | P25: Sub | Q25: Sub | R25: Sub | S25: Sub | T25: Sub | U25: Sub | V25: Sub | W25: Sub | X25: Sub | Y25: Sub | Z25: Sub | AA25: Sub | AB25: Sub | AC25: Sonos Sub | AD25: Sub
A26: fet-name-gravity | B26: Learn More / Compare & Features | C26: Sub Mini | D26: Sub Mini | E26: Sub Mini | F26: Sub Mini | G26: Sub Mini | H26: Sub Mini | I26: Sonos Sub Mini | J26: Sonos Sub Mini | K26: Sonos Sub Mini | L26: Sub Mini | M26: Sub Mini | N26: Sub Mini | O26: Sonos Sub Mini | P26: Sub Mini | Q26: Sub Mini | R26: Sub Mini | S26: Sub Mini | T26: Sub Mini | U26: Sub Mini | V26: Sub Mini | W26: Sub Mini | X26: Sub Mini | Y26: Sub Mini | Z26: Sub Mini | AA26: Sub Mini | AB26: Sub Mini | AC26: Sonos Sub Mini | AD26: Sub Mini
A27: fet-name-optimo1 | B27: Learn More / Compare & Features | C27: Era 100 | D27: Era 100 | E27: Era 100 | F27: Era 100 | G27: Era 100 | H27: Era 100 | I27: Sonos Era 100 | J27: Sonos Era 100 | K27: Sonos Era 100 | L27: Era 100 | M27: Era 100 | N27: Era 100 | O27: Sonos Era 100 | P27: Era 100 | Q27: Era 100 | R27: Era 100 | S27: Era 100 | T27: Era 100 | U27: Era 100 | V27: Era 100 | W27: Era 100 | X27: Era 100 | Y27: Era 100 | Z27: Era 100 | AA27: Era 100 | AB27: Era 100 | AC27: Sonos Era 100 | AD27: Era 100
A28: fet-name-optimo2 | B28: Learn More / Compare & Features | C28: Era 300 | D28: Era 300 | E28: Era 300 | F28: Era 300 | G28: Era 300 | H28: Era 300 | I28: Sonos Era 300 | J28: Sonos Era 300 | K28: Sonos Era 300 | L28: Era 300 | M28: Era 300 | N28: Era 300 | O28: Sonos Era 300 | P28: Era 300 | Q28: Era 300 | R28: Era 300 | S28: Era 300 | T28: Era 300 | U28: Era 300 | V28: Era 300 | W28: Era 300 | X28: Era 300 | Y28: Era 300 | Z28: Era 300 | AA28: Era 300 | AB28: Era 300 | AC28: Sonos Era 300 | AD28: Era 300
A29: fet-name-five | B29: Learn More / Compare & Features | C29: Five | D29: Five | E29: Five | F29: Five | G29: Five | H29: Five | I29: Sonos Five | J29: Sonos Five | K29: Sonos Five | L29: Five | M29: Five | N29: Five | O29: Sonos Five | P29: Five | Q29: Five | R29: Five | S29: Five | T29: Five | U29: Five | V29: Five | W29: Five | X29: Five | Y29: Five | Z29: Five | AA29: Five | AB29: Five | AC29: Sonos Five | AD29: Five
A30: fet-name-roam | B30: Learn More / Compare & Features | C30: Roam | D30: Roam | E30: Roam | F30: Roam | G30: Roam | H30: Roam | I30: Sonos Roam | J30: Sonos Roam | K30: Sonos Roam | L30: Roam | M30: Roam | N30: Roam | O30: Sonos Roam | P30: Roam | Q30: Roam | R30: Roam | S30: Roam | T30: Roam | U30: Roam | V30: Roam | W30: Roam | X30: Roam | Y30: Roam | Z30: Roam | AA30: Roam | AB30: Roam | AC30: Sonos Roam | AD30: Roam
A31: fet-name-roam2 | C31: Roam 2 | D31: Roam 2 | E31: Roam 2 | F31: Roam 2 | G31: Roam 2 | H31: Roam 2 | I31: Sonos Roam 2 | J31: Sonos Roam 2 | K31: Sonos Roam 2 | L31: Roam 2 | M31: Roam 2 | N31: Roam 2 | O31: Sonos Roam 2 | P31: Roam 2 | Q31: Roam 2 | R31: Roam 2 | S31: Roam 2 | T31: Roam 2 | U31: Roam 2 | V31: Roam 2 | W31: Roam 2 | X31: Roam 2 | Y31: Roam 2 | Z31: Roam 2 | AA31: Roam 2 | AB31: Roam 2 | AC31: Sonos Roam 2 | AD31: Roam 2
A32: fet-name-roamsl | B32: Learn More / Compare & Features | C32: Roam SL | D32: Roam SL | E32: Roam SL | F32: Roam SL | G32: Roam SL | H32: Roam SL | I32: Sonos Roam SL | J32: Sonos Roam SL | K32: Sonos Roam SL | L32: Roam SL | M32: Roam SL | N32: Roam SL | O32: Sonos Roam SL | P32: Roam SL | Q32: Roam SL | R32: Roam SL | S32: Roam SL | T32: Roam SL | U32: Roam SL | V32: Roam SL | W32: Roam SL | X32: Roam SL | Y32: Roam SL | Z32: Roam SL | AA32: Roam SL | AB32: Roam SL | AC32: Sonos Roam SL | AD32: Roam SL
A33: fet-name-duke | C33: Sonos Ace | D33: Sonos Ace | E33: Sonos Ace | F33: Sonos Ace | G33: Sonos Ace | H33: Sonos Ace | I33: Sonos Ace | J33: Sonos Ace | K33: Sonos Ace | L33: Sonos Ace | M33: Sonos Ace | N33: Sonos Ace | O33: Sonos Ace | P33: Sonos Ace | Q33: Sonos Ace | R33: Sonos Ace | S33: Sonos Ace | T33: Sonos Ace | U33: Sonos Ace | V33: Sonos Ace | W33: Sonos Ace | X33: Sonos Ace | Y33: Sonos Ace | Z33: Sonos Ace | AA33: Sonos Ace | AB33: Sonos Ace | AC33: Sonos Ace | AD33: Sonos Ace
A34: fet-name-move | B34: Learn More / Compare & Features | C34: Move | D34: Move | E34: Move | F34: Move | G34: Move | H34: Move | I34: Sonos Move | J34: Sonos Move | K34: Sonos Move | L34: Move | M34: Move | N34: Move | O34: Sonos Move | P34: Move | Q34: Move | R34: Move | S34: Move | T34: Move | U34: Move | V34: Move | W34: Move | X34: Move | Y34: Move | Z34: Move | AA34: Move | AB34: Move | AC34: Sonos Move | AD34: Move
A35: fet-name-prima | B35: Learn More / Compare & Features | C35: Move 2 | D35: Move 2 | E35: Move 2 | F35: Move 2 | G35: Move 2 | H35: Move 2 | I35: Sonos Move 2 | J35: Sonos Move 2 | K35: Sonos Move 2 | L35: Move 2 | M35: Move 2 | N35: Move 2 | O35: Sonos Move 2 | P35: Move 2 | Q35: Move 2 | R35: Move 2 | S35: Move 2 | T35: Move 2 | U35: Move 2 | V35: Move 2 | W35: Move 2 | X35: Move 2 | Y35: Move 2 | Z35: Move 2 | AA35: Move 2 | AB35: Move 2 | AC35: Sonos Move 2 | AD35: Move 2
A36: fet-name-amp | C36: Amp | D36: Amp | E36: Amp | F36: Amp | G36: Amp | H36: Amp | I36: Sonos Amp | J36: Sonos Amp | K36: Sonos Amp | L36: Amp | M36: Amp | N36: Amp | O36: Sonos Amp | P36: Amp | Q36: Amp | R36: Amp | S36: Amp | T36: Amp | U36: Amp | V36: Amp | W36: Amp | X36: Amp | Y36: Amp | Z36: Amp | AA36: Amp | AB36: Amp | AC36: Sonos Amp | AD36: Amp
A37: fet-badge-dolby-atmos | B37: Lean More / Icons under descritpion | C37: Dolby Atmos | D37: Dolby Atmos | E37: Dolby Atmos | F37: Dolby Atmos | G37: Dolby Atmos | H37: Dolby Atmos | I37: Dolby Atmos | J37: Dolby Atmos | K37: Dolby Atmos | L37: Dolby Atmos | M37: Dolby Atmos | N37: Dolby Atmos | O37: Dolby Atmos（ドルビーアトモス） | P37: Dolby Atmos | Q37: Dolby Atmos | R37: Dolby Atmos | S37: Dolby Atmos | T37: Dolby Atmos | U37: Dolby Atmos | V37: Dolby Atmos | W37: Dolby Atmos | X37: 杜比全景声 | Y37: Dolby Atmos | Z37: Dolby Atmos | AA37: Dolby Atmos | AB37: Dolby Atmos | AC37: Dolby Atmos | AD37: Dolby Atmos
A38: fet-badge-dolby-head-tracking | C38: Dolby head tracking | D38: Dolby head tracking | E38: Dolby head tracking | F38: Dynamisk hovedsporing | G38: Dolby Head Tracking | H38: Dolby Head Tracking | I38: Suivi dynamique des mouvements de la tête | J38: Suivi dynamique des mouvements de la tête | K38: Suivi dynamique des mouvements de la tête | L38: Suivi dynamique de la tête | M38: Rilevamento dinamico della posizione della testa | N38: Rilevamento dinamico della posizione della testa | O38: Dolbyヘッドトラッキング | P38: Rastreo de cabeza Dolby | Q38: Dolby Head Tracking | R38: Dynamisk hodesporing | S38: Seguimiento de la cabeza Dolby | T38: Dynamisk huvudspårning | U38: Dolby head tracking | V38: Dolby head tracking | W38: Dolby head tracking | X38: 杜比头部追踪 | Y38: Dynamické sledování hlavy | Z38: Dolbyn pään asennon seuranta | AA38: Dynamiczne śledzenie ruchu głowy | AB38: Dolby Head Tracking | AC38: Suivi dynamique des mouvements de la tête | AD38: Rastreo de cabeza Dolby
A39: fet-badge-spatial-audio-with-dynamic-head-tracking-1 | C39: Spatial audio with dynamic head tracking¹ | D39: Spatial audio with dynamic head tracking¹ | E39: Spatial audio with dynamic head tracking¹ | F39: Rumlig lyd med dynamisk hovedsporing¹ | G39: 3D-Audio mit dynamischem Head Tracking¹ | H39: 3D-Audio mit dynamischem Head Tracking¹ | I39: Audio spatial avec suivi dynamique des mouvements de la tête¹ | J39: Audio spatial avec suivi dynamique des mouvements de la tête¹ | K39: Audio spatial avec suivi dynamique des mouvements de la tête¹ | L39: Audio spatial avec suivi dynamique de la tête¹ | M39: Audio spaziale con rilevamento dinamico della posizione della testa¹ | N39: Audio spaziale con rilevamento dinamico della posizione della testa¹ | O39: 空間オーディオとダイナミックヘッドトラッキング¹ | P39: Audio espacial con seguimiento dinámico de la cabeza¹ | Q39: Ruimtelijke audio met dynamische hoofdtracking | R39: Romtilpasset lyd med dynamisk hodesporing¹ | S39: Audio espacial con seguimiento dinámico de la cabeza¹ | T39: Rymligt ljud med dynamisk huvudspårning¹ | U39: Spatial audio with dynamic head tracking¹ | V39: Spatial audio with dynamic head tracking¹ | W39: Spatial audio with dynamic head tracking¹ | X39: 支持动态头部追踪的空间音频¹ | Y39: Prostorový zvuk s dynamickým sledováním hlavy¹ | Z39: Tilaääni dynaamisella pään asennon seurannalla¹ | AA39: Dźwięk przestrzenny z dynamicznym śledzeniem ruchu głowy¹ | AB39: 3D-Audio mit dynamischem Head Tracking¹ | AC39: Audio spatial avec suivi dynamique des mouvements de la tête¹ | AD39: Audio espacial con seguimiento dinámico de la cabeza1
A40: fet-badge-lossless-audio-2 | C40: Lossless audio² | D40: Lossless audio² | E40: Lossless audio² | F40: Tabsfri lyd² | G40: Verlustfreies Audio² | H40: Verlustfreies Audio² | I40: Contenus audio sans perte² | J40: Contenus audio sans perte² | K40: Contenus audio sans perte² | L40: Audio sans perte² | M40: Audio lossless² | N40: Audio lossless² | O40: ロスレスオーディオ² | P40: Audio lossless² | Q40: Lossless audio² | R40: Tapsfri lyd² | S40: Sonido sin pérdidas² | T40: Losslessljud² | U40: Lossless audio² | V40: Lossless audio² | W40: Lossless audio² | X40: 无损音频² | Y40: Bezztrátový zvuk² | Z40: Häviötön ääni² | AA40: Dźwięk bezstratny² | AB40: Verlustfreies Audio² | AC40: Contenus audio sans perte² | AD40: Audio lossless²
A41: fet-badge-enhanced-call-clarity | C41: Enhanced call clarity | D41: Enhanced call clarity | E41: Enhanced call clarity | F41: Tydeligere opkald | G41: Verbesserte Sprachqualität | H41: Verbesserte Sprachqualität | I41: Un son encore plus clair pour les appels | J41: Un son encore plus clair pour les appels | K41: Un son encore plus clair pour les appels | L41: Clarté accrue des appels | M41: Ottimizzazione della nitidezza delle chiamate | N41: Ottimizzazione della nitidezza delle chiamate | O41: より明瞭な音声 | P41: Nitidez de llamada mejorada | Q41: Duidelijkere telefoongesprekken | R41: Økt anropsklarhet | S41: Mejor calidad de las llamadas | T41: Ökad klarhet för samtal | U41: Enhanced call clarity | V41: Enhanced call clarity | W41: Enhanced call clarity | X41: 增强通话清晰度 | Y41: Zvýšená srozumitelnost hovorů | Z41: Kehittyneempi puhelun selkeys | AA41: Większa wyrazistość połączeń telefonicznych | AB41: Verbesserte Sprachqualität | AC41: Un son encore plus clair pour les appels | AD41: Nitidez de llamada mejorada
A42: badges.wearDetection | C42: Wear detection | D42: Wear detection | E42: Wear detection | F42: Registrering af brug | G42: Trageerkennung | H42: Trageerkennung | I42: Détection d'usure | J42: Détection d'usure | K42: Détection d'usure | L42: Détection lors du port | M42: Rilevamento automatico quando il prodotto viene indossato | N42: Rilevamento automatico quando il prodotto viene indossato | O42: 装着検出 | P42: Detección de desgaste | Q42: Draagdetectie | R42: Bruksdeteksjon | S42: Detección de desgaste | T42: Användningsavkänning | U42: Wear detection | V42: Wear detection | W42: Wear detection | X42: 佩戴检测 | Y42: Detekce nošení | Z42: Kulumisen havaitseminen | AA42: Wykrywanie noszenia | AB42: Trageerkennung | AC42: Détection d'usure | AD42: Detección de desgaste
...

Sheet Soundstage - 0801
A1: Key | B1: Description | C1: cs-CZ | D1: da-DK | E1: de-CH | F1: de-DE | G1: de-LU | H1: en-AU | I1: en-CA | J1: en-GB | K1: en-NZ | L1: en-RW | M1: en-US | N1: es-CO | O1: es-ES | P1: es-MX | Q1: fi-FI | R1: fr-BE | S1: fr-CA | T1: fr-CH | U1: fr-FR | V1: fr-LU | W1: it-CH | X1: it-IT | Y1: ja-JP | Z1: nb-NO | AA1: nl-NL | AB1: pl-PL | AC1: sv-SE | AD1: zh-CN
